<?xml version="1.0"?>
<robot name="physics">

<!-- link_base =  100 mm-->
<!-- link_1 =  430 mm-->
<!-- link_2 =  210 mm-->
<!-- link_3 =  210 mm-->
<!-- link_4 =  125 mm-->

<material name="blue">
    <color rgba="0 0 0.8 1"/>
  </material>
  <material name="black">
    <color rgba="0 0 0 1"/>
  </material>
  <material name="white">
    <color rgba="1 1 1 1"/>
  </material>

<link name="base_link"></link>

<link name="link_1">
    <visual>
      <geometry>
        <box size="0.1 0.1 0.1"/>
      </geometry>
      <origin rpy="0 0 0" xyz="0 0 0.05"/>
      <material name="blue"/>
    </visual>
    <collision>
      <geometry>
        <box size="0.1 0.1 0.1"/>
        <origin rpy="0 0 0" xyz="0 0 0.05"/>
      </geometry>
    </collision>
    <inertial>
      <mass value="10"/>
      <inertia ixx="1.0" ixy="0.0" ixz="0.0" iyy="1.0" iyz="0.0" izz="1.0"/>
    </inertial>
</link>

<link name="link_2">
    <visual>
      <geometry>
        <box size="0.1 0.1 0.43"/>
      </geometry>
      <origin rpy="0 0 0" xyz="0 0 0.215"/>
      <material name="blue"/>
    </visual>
    <collision>
      <geometry>
        <box size="0.1 0.1 0.43"/>
        <origin rpy="0 0 0" xyz="0 0 0.215"/>
      </geometry>
    </collision>
    <inertial>
      <mass value="10"/>
      <inertia ixx="1.0" ixy="0.0" ixz="0.0" iyy="1.0" iyz="0.0" izz="1.0"/>
    </inertial>
  </link>

<link name="link_3">
    <visual>
      <geometry>
        <box size="0.08 0.08 0.21"/>
      </geometry>
      <origin rpy="0 0 0" xyz="0 0 0.105"/>
      <material name="blue"/>
    </visual>
    <collision>
      <geometry>
        <box size="0.08 0.08 0.21"/>
        <origin rpy="0 0 0" xyz="0 0 0.105"/>
      </geometry>
    </collision>
    <inertial>
      <mass value="10"/>
      <inertia ixx="1.0" ixy="0.0" ixz="0.0" iyy="1.0" iyz="0.0" izz="1.0"/>
    </inertial>
  </link>

<link name="link_4">
    <visual>
      <geometry>
        <box size="0.08 0.08 0.21"/>
      </geometry>
      <origin rpy="0 0 0" xyz="0 0 0.105"/>
      <material name="blue"/>
    </visual>
    <collision>
      <geometry>
        <box size="0.08 0.08 0.21"/>
        <origin rpy="0 0 0" xyz="0 0 0.105"/>
      </geometry>
    </collision>
    <inertial>
      <mass value="10"/>
      <inertia ixx="1.0" ixy="0.0" ixz="0.0" iyy="1.0" iyz="0.0" izz="1.0"/>
    </inertial>
  </link>

<link name="link_5">
    <visual>
      <geometry>
        <box size="0.08 0.08 0.125"/>
      </geometry>
      <origin rpy="0 0 0" xyz="0 0 0.0625"/>
      <material name="blue"/>
    </visual>
    <collision>
      <geometry>
        <box size="0.08 0.08 0.125"/>
        <origin rpy="0 0 0" xyz="0 0 0.0625"/>
      </geometry>
    </collision>
    <inertial>
      <mass value="10"/>
      <inertia ixx="1.0" ixy="0.0" ixz="0.0" iyy="1.0" iyz="0.0" izz="1.0"/>
    </inertial>
  </link>

<link name="link_6">
    <visual>
      <geometry>
        <box size="0.08 0.08 0.001"/>
      </geometry>
      <origin rpy="0 0 0" xyz="0 0 0.0006"/>
      <material name="blue"/>
    </visual>
    <collision>
      <geometry>
        <box size="0.08 0.08 0.001"/>
        <origin rpy="0 0 0" xyz="0 0 0.0006"/>
      </geometry>
    </collision>
    <inertial>
      <mass value="10"/>
      <inertia ixx="1.0" ixy="0.0" ixz="0.0" iyy="1.0" iyz="0.0" izz="1.0"/>
    </inertial>
  </link>

<joint name="joint1" type="revolute">
    <axis xyz="0 0 1"/>
    <limit effort="1000.0" lower="-3.14" upper="3.14" velocity="0.5"/>
    <origin rpy="0 0 0" xyz="0 0 0"/>
    <parent link="base_link"/>
    <child link="link_1"/>
  </joint>


<joint name="joint2" type="revolute">
    <axis xyz="1 0 0"/>
    <limit effort="1000.0" lower="-1.570796" upper="1.570796" velocity="0.5"/>
    <origin rpy="0 0 0" xyz="0 0 0.1"/>
    <parent link="link_1"/>
    <child link="link_2"/>
    <origin xyz="0 0 0"/>
  </joint>

<joint name="joint3" type="revolute">
    <axis xyz="1 0 0"/>
    <limit effort="1000.0" lower="-1.9" upper="1.9" velocity="0.5"/>
    <origin rpy="0 0 0" xyz="0.0 0.0 0.43"/>
    <parent link="link_2"/>
    <child link="link_3"/>
    <origin xyz="0 0 0"/>
  </joint>

<joint name="joint4" type="revolute">
    <axis xyz="0 0 1"/>
    <limit effort="1000.0" lower="-2" upper="2" velocity="0.5"/>
    <origin rpy="0 0 0" xyz="0 0.0 0.21"/>
    <parent link="link_3"/>
    <child link="link_4"/>
    <origin xyz="0 0 0"/>
  </joint>

<joint name="joint5" type="revolute">
    <axis xyz="1 0 0"/>
    <limit effort="1000.0" lower="-1.570796" upper="1.570796" velocity="0.5"/>
    <origin rpy="0 0 0" xyz="0 0 0.21"/>
    <parent link="link_4"/>
    <child link="link_5"/>
    <origin xyz="0 0 0.05"/>
  </joint>

<joint name="joint6" type="revolute">
    <axis xyz="0 0 1"/>
    <limit effort="1000.0" lower="-3.141592" upper="3.141592" velocity="0.5"/>
    <origin rpy="0 0 0" xyz="0 0 0.125"/>
    <parent link="link_5"/>
    <child link="link_6"/>
    <origin xyz="0 0 0.05"/>
  </joint>


</robot>
